[2025-02-05T12:25:33.023+0000] {local_task_job_runner.py:123} INFO - ::group::Pre task execution logs
[2025-02-05T12:25:33.066+0000] {taskinstance.py:2613} INFO - Dependencies all met for dep_context=non-requeueable deps ti=<TaskInstance: Temp_elt_postgres.move_files manual__2025-02-05T12:25:05.296195+00:00 [queued]>
[2025-02-05T12:25:33.084+0000] {taskinstance.py:2613} INFO - Dependencies all met for dep_context=requeueable deps ti=<TaskInstance: Temp_elt_postgres.move_files manual__2025-02-05T12:25:05.296195+00:00 [queued]>
[2025-02-05T12:25:33.085+0000] {taskinstance.py:2866} INFO - Starting attempt 1 of 1
[2025-02-05T12:25:33.156+0000] {taskinstance.py:2889} INFO - Executing <Task(BashOperator): move_files> on 2025-02-05 12:25:05.296195+00:00
[2025-02-05T12:25:33.173+0000] {standard_task_runner.py:104} INFO - Running: ['airflow', 'tasks', 'run', 'Temp_elt_postgres', 'move_files', 'manual__2025-02-05T12:25:05.296195+00:00', '--job-id', '170', '--raw', '--subdir', 'DAGS_FOLDER/weather_etl_postgres.py', '--cfg-path', '/tmp/tmpgi4f9z9_']
[2025-02-05T12:25:33.178+0000] {standard_task_runner.py:105} INFO - Job 170: Subtask move_files
[2025-02-05T12:25:33.182+0000] {logging_mixin.py:190} WARNING - /home/airflow/.local/lib/python3.12/site-packages/airflow/task/task_runner/standard_task_runner.py:70 DeprecationWarning: This process (pid=110) is multi-threaded, use of fork() may lead to deadlocks in the child.
[2025-02-05T12:25:33.183+0000] {standard_task_runner.py:72} INFO - Started process 120 to run task
[2025-02-05T12:25:33.293+0000] {task_command.py:467} INFO - Running <TaskInstance: Temp_elt_postgres.move_files manual__2025-02-05T12:25:05.296195+00:00 [running]> on host 21d54d79e796
[2025-02-05T12:25:33.483+0000] {taskinstance.py:3132} INFO - Exporting env vars: AIRFLOW_CTX_DAG_OWNER='airflow' AIRFLOW_CTX_DAG_ID='Temp_elt_postgres' AIRFLOW_CTX_TASK_ID='move_files' AIRFLOW_CTX_EXECUTION_DATE='2025-02-05T12:25:05.296195+00:00' AIRFLOW_CTX_TRY_NUMBER='1' AIRFLOW_CTX_DAG_RUN_ID='manual__2025-02-05T12:25:05.296195+00:00'
[2025-02-05T12:25:33.487+0000] {taskinstance.py:731} INFO - ::endgroup::
[2025-02-05T12:25:33.521+0000] {subprocess.py:78} INFO - Tmp dir root location: /tmp
[2025-02-05T12:25:33.524+0000] {subprocess.py:88} INFO - Running command: ['/usr/bin/bash', '-c', 'mv /opt/airflow/data/raw /shared-data/raw']
[2025-02-05T12:25:33.547+0000] {subprocess.py:99} INFO - Output:
[2025-02-05T12:25:33.559+0000] {subprocess.py:106} INFO - mv: inter-device move failed: '/opt/airflow/data/raw' to '/shared-data/raw/raw'; unable to remove target: Directory not empty
[2025-02-05T12:25:33.560+0000] {subprocess.py:110} INFO - Command exited with return code 1
[2025-02-05T12:25:33.582+0000] {taskinstance.py:3311} ERROR - Task failed with exception
Traceback (most recent call last):
  File "/home/airflow/.local/lib/python3.12/site-packages/airflow/models/taskinstance.py", line 767, in _execute_task
    result = _execute_callable(context=context, **execute_callable_kwargs)
             ^^^^^^^^^^^^^^^^^^^^^^^^^^^^^^^^^^^^^^^^^^^^^^^^^^^^^^^^^^^^^
  File "/home/airflow/.local/lib/python3.12/site-packages/airflow/models/taskinstance.py", line 733, in _execute_callable
    return ExecutionCallableRunner(
           ^^^^^^^^^^^^^^^^^^^^^^^^
  File "/home/airflow/.local/lib/python3.12/site-packages/airflow/utils/operator_helpers.py", line 252, in run
    return self.func(*args, **kwargs)
           ^^^^^^^^^^^^^^^^^^^^^^^^^^
  File "/home/airflow/.local/lib/python3.12/site-packages/airflow/models/baseoperator.py", line 422, in wrapper
    return func(self, *args, **kwargs)
           ^^^^^^^^^^^^^^^^^^^^^^^^^^^
  File "/home/airflow/.local/lib/python3.12/site-packages/airflow/operators/bash.py", line 276, in execute
    raise AirflowException(
airflow.exceptions.AirflowException: Bash command failed. The command returned a non-zero exit code 1.
[2025-02-05T12:25:33.595+0000] {taskinstance.py:1225} INFO - Marking task as FAILED. dag_id=Temp_elt_postgres, task_id=move_files, run_id=manual__2025-02-05T12:25:05.296195+00:00, execution_date=20250205T122505, start_date=20250205T122533, end_date=20250205T122533
[2025-02-05T12:25:33.655+0000] {taskinstance.py:340} INFO - ::group::Post task execution logs
[2025-02-05T12:25:33.657+0000] {standard_task_runner.py:124} ERROR - Failed to execute job 170 for task move_files (Bash command failed. The command returned a non-zero exit code 1.; 120)
Traceback (most recent call last):
  File "/home/airflow/.local/lib/python3.12/site-packages/airflow/task/task_runner/standard_task_runner.py", line 117, in _start_by_fork
    ret = args.func(args, dag=self.dag)
          ^^^^^^^^^^^^^^^^^^^^^^^^^^^^^
  File "/home/airflow/.local/lib/python3.12/site-packages/airflow/cli/cli_config.py", line 49, in command
    return func(*args, **kwargs)
           ^^^^^^^^^^^^^^^^^^^^^
  File "/home/airflow/.local/lib/python3.12/site-packages/airflow/utils/cli.py", line 116, in wrapper
    return f(*args, **kwargs)
           ^^^^^^^^^^^^^^^^^^
  File "/home/airflow/.local/lib/python3.12/site-packages/airflow/cli/commands/task_command.py", line 483, in task_run
    task_return_code = _run_task_by_selected_method(args, _dag, ti)
                       ^^^^^^^^^^^^^^^^^^^^^^^^^^^^^^^^^^^^^^^^^^^^
  File "/home/airflow/.local/lib/python3.12/site-packages/airflow/cli/commands/task_command.py", line 256, in _run_task_by_selected_method
    return _run_raw_task(args, ti)
           ^^^^^^^^^^^^^^^^^^^^^^^
  File "/home/airflow/.local/lib/python3.12/site-packages/airflow/cli/commands/task_command.py", line 341, in _run_raw_task
    return ti._run_raw_task(
           ^^^^^^^^^^^^^^^^^
  File "/home/airflow/.local/lib/python3.12/site-packages/airflow/utils/session.py", line 97, in wrapper
    return func(*args, session=session, **kwargs)
           ^^^^^^^^^^^^^^^^^^^^^^^^^^^^^^^^^^^^^^
  File "/home/airflow/.local/lib/python3.12/site-packages/airflow/models/taskinstance.py", line 3005, in _run_raw_task
    return _run_raw_task(
           ^^^^^^^^^^^^^^
  File "/home/airflow/.local/lib/python3.12/site-packages/airflow/models/taskinstance.py", line 273, in _run_raw_task
    TaskInstance._execute_task_with_callbacks(
  File "/home/airflow/.local/lib/python3.12/site-packages/airflow/models/taskinstance.py", line 3159, in _execute_task_with_callbacks
    result = self._execute_task(context, task_orig)
             ^^^^^^^^^^^^^^^^^^^^^^^^^^^^^^^^^^^^^^
  File "/home/airflow/.local/lib/python3.12/site-packages/airflow/models/taskinstance.py", line 3183, in _execute_task
    return _execute_task(self, context, task_orig)
           ^^^^^^^^^^^^^^^^^^^^^^^^^^^^^^^^^^^^^^^
  File "/home/airflow/.local/lib/python3.12/site-packages/airflow/models/taskinstance.py", line 767, in _execute_task
    result = _execute_callable(context=context, **execute_callable_kwargs)
             ^^^^^^^^^^^^^^^^^^^^^^^^^^^^^^^^^^^^^^^^^^^^^^^^^^^^^^^^^^^^^
  File "/home/airflow/.local/lib/python3.12/site-packages/airflow/models/taskinstance.py", line 733, in _execute_callable
    return ExecutionCallableRunner(
           ^^^^^^^^^^^^^^^^^^^^^^^^
  File "/home/airflow/.local/lib/python3.12/site-packages/airflow/utils/operator_helpers.py", line 252, in run
    return self.func(*args, **kwargs)
           ^^^^^^^^^^^^^^^^^^^^^^^^^^
  File "/home/airflow/.local/lib/python3.12/site-packages/airflow/models/baseoperator.py", line 422, in wrapper
    return func(self, *args, **kwargs)
           ^^^^^^^^^^^^^^^^^^^^^^^^^^^
  File "/home/airflow/.local/lib/python3.12/site-packages/airflow/operators/bash.py", line 276, in execute
    raise AirflowException(
airflow.exceptions.AirflowException: Bash command failed. The command returned a non-zero exit code 1.
[2025-02-05T12:25:33.705+0000] {local_task_job_runner.py:266} INFO - Task exited with return code 1
[2025-02-05T12:25:33.758+0000] {taskinstance.py:3895} INFO - 0 downstream tasks scheduled from follow-on schedule check
[2025-02-05T12:25:33.790+0000] {local_task_job_runner.py:245} INFO - ::endgroup::
